Workbook

Sheet Dim_Setores
A1: nome_setor | B1: id_setor_cod | C1: tamanho_mercado_bi | D1: risco_regulatorio | E1: crescimento_anual
A2: Agri-IoT | B2: S-01 | C2: 15.2 | D2: Baixo | E2: 0.12
A3: Water-Ops | B3: S-02 | C3: 8.4 | D3: Alto | E3: 0.05
A4: SmartCity | B4: S-03 | C4: 45 | D4: Médio | E4: 0.18
A5: Enviro-Tech | B5: S-04 | C5: 12.1 | D5: Médio | E5: 0.09
A6: Power-Grid | B6: S-05 | C6: 22.5 | D6: Alto | E6: 0.07

Sheet Fact_Incidentes
A1: id_ticket | B1: id_startup | C1: data_abertura | D1: tipo_falha | E1: severidade | F1: status_ticket
A2: TKT-25795 | B2: 1 | C2: 45640 | D2: Sensor | E2: Baixa | F2: Fechado
A3: TKT-64886 | B3: 1 | C3: 45413 | D3: Sensor | E3: Média | F3: Fechado
A4: TKT-54131 | B4: 1 | C4: 45651 | D4: Sensor | E4: Alta | F4: Fechado
A5: TKT-69735 | B5: 1 | C5: 45585 | D5: Bateria | E5: Baixa | F5: Em Análise
A6: TKT-93104 | B6: 1 | C6: 45605 | D6: Software | E6: Baixa | F6: Fechado
A7: TKT-35658 | B7: 1 | C7: 45461 | D7: Carcaça | E7: Baixa | F7: Fechado
A8: TKT-75725 | B8: 1 | C8: 45466 | D8: Sensor | E8: Baixa | F8: Fechado
A9: TKT-41551 | B9: 1 | C9: 45422 | D9: Software | E9: Média | F9: Fechado
A10: TKT-90038 | B10: 1 | C10: 45565 | D10: Carcaça | E10: Crítica | F10: Em Análise
A11: TKT-83969 | B11: 1 | C11: 45556 | D11: Bateria | E11: Crítica | F11: Fechado
A12: TKT-33483 | B12: 1 | C12: 45555 | D12: Sensor | E12: Alta | F12: Fechado
A13: TKT-79479 | B13: 2 | C13: 45293 | D13: Bateria | E13: Baixa | F13: Fechado
... A350: TKT-93186 | B350: 45 | C350: 45413 | D350: Sensor | E350: Média | F350: Fechado

Sheet Avaliacoes_Startups
A1: id_startup | B1: nome_startup | C1: setor | D1: status | E1: data_avaliacao | F1: 1.1_precisao_basica | G1: 1.2_calibracao | H1: 1.3_estabilidade_leitura | I1: 1.4_latencia_sinal | J1: 1.5_relacao_sinal_ruido | K1: 2.1_custo_bom | L1: 2.2_custo_opex | M1: 2.3_tempo_deploy | N1: 2.4_escalabilidade_fabril | O1: 2.5_competitividade_preco | P1: 3.1_mtbf_teorico | Q1: 3.2_tratamento_erros | R1: 3.3_estabilidade_firmware | S1: 3.4_tempo_recuperacao | T1: 3.5_stress_test | U1: 4.1_tempo_instalacao | V1: 4.2_facilidade_config | W1: 4.3_clareza_dashboard | X1: 4.4_feedback_usuario | Y1: 4.5_doc_tecnica | Z1: 5.1_autonomia_bateria | AA1: 5.2_eficiencia_carga | AB1: 5.3_consumo_standby | AC1: 5.4_dimensionamento_fonte | AD1: 5.5_modo_sleep | AE1: 6.1_protecao_ip_agua | AF1: 6.2_resistencia_termica | AG1: 6.3_integridade_mecanica | AH1: 6.4_resistencia_impacto | AI1: 6.5_durabilidade_conector | AJ1: 7.1_perda_pacotes | AK1: 7.2_latencia_nuvem | AL1: 7.3_integridade_backup | AM1: 7.4_resiliencia_api | AN1: 7.5_seguranca_cripto | AO1: 8.1_risco_supply_chain | AP1: 8.2_frequencia_manutencao | AQ1: 8.3_indice_reparabilidade | AR1: 8.4_tempo_montagem | AS1: 8.5_ciclo_vida_material
A2: 1 | B2: AlphaTech | C2: Agri-IoT | D2: Ativa | E2: 2025-01-10 | F2: 3 | G2: 5 | H2: 5 | I2: 4 | J2: 3 | K2: 4 | L2: 5 | M2: 3 | N2: 3 | O2: 3 | P2: 4 | Q2: 3 | R2: 3 | S2: 5 | T2: 5 | U2: 4 | V2: 4 | W2: 4 | X2: 4 | Y2: 5 | Z2: 5 | AA2: 4 | AB2: 4 | AC2: 4 | AD2: 5 | AE2: 5 | AF2: 3 | AG2: 3 | AH2: 3 | AI2: 3 | AJ2: 3 | AK2: 4 | AL2: 4 | AM2: 4 | AN2: 4 | AO2: 3 | AP2: 3 | AQ2: 5 | AR2: 4 | AS2: 4
A3: 2 | B3: BetaSolutions | C3: Water-Ops | D3: Ativa | E3: 2025-01-11 | F3: 4 | G3: 3 | H3: 4 | I3: 5 | J3: 5 | K3: 3 | L3: 4 | M3: 5 | N3: 3 | O3: 5 | P3: 5 | Q3: 4 | R3: 5 | S3: 3 | T3: 4 | U3: 5 | V3: 5 | W3: 5 | X3: 3 | Y3: 5 | Z3: 3 | AA3: 5 | AB3: 5 | AC3: 4 | AD3: 5 | AE3: 3 | AF3: 5 | AG3: 5 | AH3: 3 | AI3: 5 | AJ3: 3 | AK3: 5 | AL3: 3 | AM3: 3 | AN3: 4 | AO3: 5 | AP3: 3 | AQ3: 3 | AR3: 4 | AS3: 3
A4: 3 | B4: GammaSystems | C4: SmartCity | D4: Inativa | E4: 2024-11-05 | F4: 1 | G4: 1 | H4: 3 | I4: 3 | J4: 3 | K4: 2 | L4: 1 | M4: 3 | N4: 1 | O4: 3 | P4: 3 | Q4: 3 | R4: 1 | S4: 3 | T4: 3 | U4: 2 | V4: 2 | W4: 2 | X4: 2 | Y4: 1 | Z4: 2 | AA4: 2 | AB4: 3 | AC4: 1 | AD4: 1 | AE4: 3 | AF4: 3 | AG4: 3 | AH4: 1 | AI4: 1 | AJ4: 2 | AK4: 1 | AL4: 1 | AM4: 3 | AN4: 1 | AO4: 2 | AP4: 1 | AQ4: 3 | AR4: 3 | AS4: 1
A5: 4 | B5: DeltaDevices | C5: Enviro-Tech | D5: Ativa | E5: 2025-01-12 | F5: 3 | G5: 5 | H5: 5 | I5: 3 | J5: 3 | K5: 3 | L5: 3 | M5: 3 | N5: 5 | O5: 4 | P5: 3 | Q5: 3 | R5: 3 | S5: 4 | T5: 3 | U5: 5 | V5: 4 | W5: 5 | X5: 3 | Y5: 5 | Z5: 5 | AA5: 4 | AB5: 3 | AC5: 3 | AD5: 3 | AE5: 5 | AF5: 4 | AG5: 5 | AH5: 5 | AI5: 3 | AJ5: 4 | AK5: 3 | AL5: 4 | AM5: 4 | AN5: 3 | AO5: 4 | AP5: 4 | AQ5: 5 | AR5: 3 | AS5: 3
A6: 5 | B6: EpsilonEnergy | C6: Power-Grid | D6: Ativa | E6: 2025-01-08 | F6: 4 | G6: 3 | H6: 4 | I6: 4 | J6: 4 | K6: 3 | L6: 3 | M6: 4 | N6: 5 | O6: 4 | P6: 4 | Q6: 3 | R6: 3 | S6: 3 | T6: 5 | U6: 5 | V6: 4 | W6: 5 | X6: 4 | Y6: 4 | Z6: 5 | AA6: 5 | AB6: 5 | AC6: 5 | AD6: 5 | AE6: 5 | AF6: 5 | AG6: 4 | AH6: 3 | AI6: 3 | AJ6: 3 | AK6: 3 | AL6: 3 | AM6: 5 | AN6: 3 | AO6: 4 | AP6: 4 | AQ6: 4 | AR6: 5 | AS6: 3
A7: 6 | B7: ZetaSensors | C7: Agri-IoT | D7: Inativa | E7: 2024-10-20 | F7: 2 | G7: 1 | H7: 1 | I7: 2 | J7: 1 | K7: 1 | L7: 2 | M7: 3 | N7: 2 | O7: 1 | P7: 3 | Q7: 3 | R7: 3 | S7: 3 | T7: 3 | U7: 1 | V7: 3 | W7: 2 | X7: 1 | Y7: 2 | Z7: 2 | AA7: 2 | AB7: 2 | AC7: 1 | AD7: 2 | AE7: 2 | AF7: 2 | AG7: 2 | AH7: 2 | AI7: 1 | AJ7: 3 | AK7: 2 | AL7: 1 | AM7: 1 | AN7: 3 | AO7: 2 | AP7: 3 | AQ7: 2 | AR7: 3 | AS7: 3
A8: 7 | B8: EtaFlow | C8: Water-Ops | D8: Ativa | E8: 2025-01-09 | F8: 5 | G8: 4 | H8: 3 | I8: 4 | J8: 4 | K8: 4 | L8: 3 | M8: 3 | N8: 5 | O8: 4 | P8: 5 | Q8: 5 | R8: 3 | S8: 3 | T8: 5 | U8: 4 | V8: 3 | W8: 4 | X8: 5 | Y8: 5 | Z8: 5 | AA8: 3 | AB8: 5 | AC8: 3 | AD8: 4 | AE8: 4 | AF8: 3 | AG8: 5 | AH8: 4 | AI8: 4 | AJ8: 4 | AK8: 5 | AL8: 5 | AM8: 4 | AN8: 3 | AO8: 3 | AP8: 5 | AQ8: 3 | AR8: 4 | AS8: 4
A9: 8 | B9: ThetaLight | C9: SmartCity | D9: Ativa | E9: 2025-01-13 | F9: 3 | G9: 4 | H9: 4 | I9: 5 | J9: 3 | K9: 4 | L9: 4 | M9: 5 | N9: 4 | O9: 5 | P9: 4 | Q9: 3 | R9: 3 | S9: 3 | T9: 4 | U9: 3 | V9: 5 | W9: 3 | X9: 3 | Y9: 4 | Z9: 5 | AA9: 3 | AB9: 5 | AC9: 4 | AD9: 3 | AE9: 3 | AF9: 4 | AG9: 3 | AH9: 5 | AI9: 5 | AJ9: 5 | AK9: 3 | AL9: 3 | AM9: 5 | AN9: 4 | AO9: 3 | AP9: 5 | AQ9: 3 | AR9: 4 | AS9: 5
A10: 9 | B10: IotaWaste | C10: Enviro-Tech | D10: Ativa | E10: 2025-01-05 | F10: 4 | G10: 3 | H10: 5 | I10: 5 | J10: 4 | K10: 4 | L10: 4 | M10: 4 | N10: 3 | O10: 4 | P10: 3 | Q10: 4 | R10: 4 | S10: 5 | T10: 5 | U10: 4 | V10: 3 | W10: 4 | X10: 4 | Y10: 4 | Z10: 4 | AA10: 4 | AB10: 3 | AC10: 4 | AD10: 5 | AE10: 4 | AF10: 3 | AG10: 5 | AH10: 3 | AI10: 5 | AJ10: 4 | AK10: 5 | AL10: 3 | AM10: 4 | AN10: 5 | AO10: 4 | AP10: 3 | AQ10: 3 | AR10: 3 | AS10: 5
A11: 10 | B11: KappaPower | C11: Power-Grid | D11: Inativa | E11: 2024-12-01 | F11: 2 | G11: 3 | H11: 1 | I11: 3 | J11: 1 | K11: 1 | L11: 3 | M11: 1 | N11: 3 | O11: 1 | P11: 2 | Q11: 1 | R11: 3 | S11: 2 | T11: 3 | U11: 1 | V11: 2 | W11: 1 | X11: 3 | Y11: 3 | Z11: 3 | AA11: 1 | AB11: 1 | AC11: 3 | AD11: 1 | AE11: 3 | AF11: 1 | AG11: 1 | AH11: 3 | AI11: 2 | AJ11: 3 | AK11: 2 | AL11: 2 | AM11: 1 | AN11: 2 | AO11: 1 | AP11: 1 | AQ11: 2 | AR11: 2 | AS11: 2
A12: 11 | B12: LambdaCrops | C12: Agri-IoT | D12: Ativa | E12: 2025-01-14 | F12: 5 | G12: 5 | H12: 3 | I12: 4 | J12: 3 | K12: 3 | L12: 4 | M12: 3 | N12: 4 | O12: 3 | P12: 3 | Q12: 3 | R12: 5 | S12: 3 | T12: 3 | U12: 3 | V12: 4 | W12: 5 | X12: 5 | Y12: 5 | Z12: 5 | AA12: 4 | AB12: 3 | AC12: 4 | AD12: 3 | AE12: 4 | AF12: 5 | AG12: 3 | AH12: 4 | AI12: 5 | AJ12: 4 | AK12: 5 | AL12: 3 | AM12: 5 | AN12: 4 | AO12: 3 | AP12: 4 | AQ12: 4 | AR12: 4 | AS12: 4
A13: 12 | B13: MuAqua | C13: Water-Ops | D13: Ativa | E13: 2025-01-07 | F13: 3 | G13: 5 | H13: 5 | I13: 4 | J13: 3 | K13: 3 | L13: 5 | M13: 5 | N13: 5 | O13: 3 | P13: 3 | Q13: 5 | R13: 3 | S13: 5 | T13: 3 | U13: 3 | V13: 3 | W13: 3 | X13: 3 | Y13: 5 | Z13: 3 | AA13: 3 | AB13: 3 | AC13: 4 | AD13: 3 | AE13: 5 | AF13: 4 | AG13: 4 | AH13: 5 | AI13: 3 | AJ13: 4 | AK13: 4 | AL13: 5 | AM13: 4 | AN13: 5 | AO13: 3 | AP13: 3 | AQ13: 3 | AR13: 3 | AS13: 3
... A46: 45 | B46: ShinEnergy | C46: Power-Grid | D46: Ativa | E46: 2024-12-13 | F46: 4 | G46: 3 | H46: 3 | I46: 3 | J46: 5 | K46: 4 | L46: 4 | M46: 3 | N46: 3 | O46: 5 | P46: 4 | Q46: 3 | R46: 5 | S46: 4 | T46: 5 | U46: 4 | V46: 4 | W46: 5 | X46: 3 | Y46: 5 | Z46: 5 | AA46: 5 | AB46: 4 | AC46: 3 | AD46: 4 | AE46: 4 | AF46: 3 | AG46: 4 | AH46: 4 | AI46: 4 | AJ46: 3 | AK46: 5 | AL46: 5 | AM46: 4 | AN46: 4 | AO46: 5 | AP46: 4 | AQ46: 4 | AR46: 3 | AS46: 5

Sheet Dados
A2: 1 – Critérios de avaliação de Precisão (Accuracy)
A4: Indicadores | B4: Inaceitável – 1 Ponto | C4: Fraco – 2 Pontos | D4: Aceitável – 3 Pontos | E4: Bom – 4 Pontos | F4: Excelente – 5 Pontos
A5: 1.1_precisao_basica | B5: Erro > 20%. | C5: Erro entre 10-20%. | D5: Erro < 10%. | E5: Erro < 5%. | F5: Erro < 2%.
A6: 1.2_calibracao | B6: Erro > 25% | C6: Erro entre 15–25%. Funcionamento inadequado. | D6: Erro < 15%. Cumpre a função básica. | E6: Erro < 10%. Funcionamento robusto. | F6: Erro < 5%.
A7: 1.3_estabilidade_leitura | B7: Deriva severa (> 25%) | C7: Deriva > 15%. Dados das últimas semanas inutilizáveis, requer revisão de projeto. | D7: Deriva entre 5–15%. Exige recalibração ao final do teste (limitação significativa). | E7: Deriva < 5%. Pequenos ajustes necessários. | F7: Deriva mínima (< 2%).
A8: 1.4_latencia_sinal | B8: > 5 min. | C8: 3–5 min. Inadequado. | D8: 1–3 min. Cumpre a função básica. | E8: 30–60 s. Robusto. | F8: < 30 s.
A9: 1.5_relacao_sinal_ruido | B9: < 90% de integridade | C9: 90–95% de integridade. Perdas inadequadas, requer revisão. | D9: 95–98% de integridade. Cumpre a função, mas com perdas. | E9: 98–99,9% de integridade. Perdas mínimas. | F9: 1
A11: 2 – Critérios de avaliação de Custo-Benefício (Cost-effectiveness)
A13: Indicadores | B13: Inaceitável – 1 Ponto | C13: Fraco – 2 Pontos | D13: Aceitável – 3 Pontos | E13: Bom – 4 Pontos | F13: Excelente – 5 Pontos
A14: 2.1_custo_bom | B14: Dinheiro desperdiçado | C14: Custo muito baixo, desempenho aceitável (aceitável com muitas limitações). | D14: Custo baixo, desempenho aceitável (relação custo/limitação equilibrada). | E14: Custo baixo, desempenho bom (robusto). | F14: Custo baixo, desempenho bom ou excelente (superou expectativas).
A15: 2.2_custo_opex | B15: troca frequente de sensores | C15: Custo 30-50% do MVP/ano. Inadequado. | D15: Custo 20-30% do MVP/ano (limitação significativa). | E15: Custo 10-20% do MVP/ano. | F15: Custo < 10% do MVP/ano.
A16: 2.3_tempo_deploy | B16: Inviável. | C16: Média de 2-3 horas/unidade. Inadequado, requer revisão do design. | D16: Média de 1-2 horas/unidade (limitação de tempo). | E16: Média de 30-60 minutos/unidade. Robusto. | F16: Média de < 30 minutos/unidade, adequado.
A17: 2.4_escalabilidade_fabril | B17: Processo artesanal, inviável de replicar. | C17: 6-8 horas. Inadequado, requer revisão de engenharia. | D17: 4-6 horas. Cumpre a função, mas com limitação de escala. | E17: 2-4 horas. Processo robusto. | F17: < 2 horas. Superou expectativas.
A18: 2.5_competitividade_preco | B18: TCO similar ou superior aos concorrentes. | C18: TCO 10-20% abaixo. Diferencial inadequado. | D18: TCO 20-40% abaixo. Vantagem clara, mas com limitações (ver outras notas). | E18: TCO 40-60% abaixo. Vantagem robusta. | F18: TCO > 60% abaixo. Superou expectativas.
A20: 3 – Critérios de avaliação de Confiabilidade (Reliability)
A22: Indicadores | B22: Inaceitável – 1 Ponto | C22: Fraco – 2 Pontos | D22: Aceitável – 3 Pontos | E22: Bom – 4 Pontos | F22: Excelente – 5 Pontos
A23: 3.1_mtbf_teorico | B23: Erro > 20% | C23: Erro 10-20% | D23: Erro < 10% (limitação). | E23: Erro < 5% (robusto). | F23: Erro < 2% (superou expectativas).
A24: 3.2_tratamento_erros | B24: Perda severa (> 25%), invalidou os dados. | C24: Perda 15-25% | D24: Perda 5-15% (requer calibração, limitação). | E24: Perda < 5% (robusto). | F24: Perda < 2% (mínima).
A25: 3.3_estabilidade_firmware | B25: > 5 resets manuais | C25: 3-5 resets | D25: 1-2 resets (limitação). | E25: 0 resets, mas se recuperou sozinho. | F25: 0 resets (100% estável).
A26: 3.4_tempo_recuperacao | B26: exigiu reset manual | C26: Recuperação lenta (> 10 min) | D26: Recuperação lenta (5-10 min) (limitação). | E26: Recuperação robusta (1-5 min). | F26: Recuperação rápida (< 1 min).
A27: 3.5_stress_test | B27: > 20% da média | C27: Variabilidade 10-20% | D27: Variabilidade 5-10% (limitação). | E27: Variabilidade 2-5% (robusta). | F27: Variabilidade < 2% (excelente).
A29: 4 – Critérios de avaliação de Usabilidade (Usability)
A31: Indicadores | B31: Inaceitável – 1 Ponto | C31: Fraco – 2 Pontos | D31: Aceitável – 3 Pontos | E31: Bom – 4 Pontos | F31: Excelente – 5 Pontos
A32: 4.1_tempo_instalacao | B32: > 3h/unidade | C32: 2-3h/unidade; | D32: 1-2h/unidade; 1-2 pessoas (limitação). | E32: 30-60 min/unidade; 1 pessoa. | F32: < 30 min/unidade; 1 pessoa.
A33: 4.2_facilidade_config | B33: Requer edição de código/firmware. | C33: Requer PC/cabo ou software complexo. | D33: Requer Ponto de Acesso (AP) e configuração manual (limitação). | E33: Rápido (via app), < 5 min. | F33: Automático (Portal Cativo/WPS), < 2 min.
A34: 4.3_clareza_dashboard | B34: Usuário não consegue interpretar dados brutos. | C34: Usuário leva > 5 minutos | D34: Usuário encontra, mas acha confuso (limitação). | E34: Usuário encontra < 1 minuto (robusto). | F34: Usuário encontra < 30 segundos (prático).
A35: 4.4_feedback_usuario | B35: caixa preta | C35: "Verde" com falha | D35: LEDs requerem consulta ao manual (limitação). | E35: LEDs claros e intuitivos (ex: "Vermelho = Falha"). | F35: LEDs claros e feedback na nuvem (ex: "Status: OFFLINE").
A36: 4.5_doc_tecnica
A37: 5 – Critérios de avaliação de Eficiência Energética (Energy Efficiency)
A39: Indicadores | B39: Inaceitável – 1 Ponto | C39: Fraco – 2 Pontos | D39: Aceitável – 3 Pontos | E39: Bom – 4 Pontos | F39: Excelente – 5 Pontos
A40: 5.1_autonomia_bateria | B40: Uma ou mais réplicas (n=5) desligaram por falta de energia. | C40: Bateria < 20% (risco de desligamento). Requer revisão. | D40: Bateria 30-50% (sem reserva, limitação). | E40: Bateria nunca < 60% (robusto). | F40: Bateria nunca < 80% (excelente).
A41: 5.2_eficiencia_carga | B41: Requer > 1 dia de sol para recarga. | C41: Carga em 1 dia de sol (8h) (inadequado). | D41: Carga em 6h de sol (aceitável). | E41: Carga em 4h de sol (robusto). | F41: Carga em < 3h de sol (excelente)
A42: 5.3_consumo_standby | B42: Alto consumo (bateria > 5 dias). | C42: Consumo inadequado (autonomia < 10 dias). | D42: Consumo aceitável (autonomia 10-20 dias). | E42: Baixo consumo (autonomia 20-30 dias). | F42: Consumo ultra-baixo (autonomia > 30 dias)
A43: 5.4_dimensionamento_fonte | B43: Subdimensionado (ver 5.1). | C43: Subdimensionado (ver 5.2). | D43: Aceitável, mas sem margem de segurança. | E43: Robusto (boa margem). | F43: Excelente (ótima margem de segurança).
A44: 5.5_modo_sleep
A45: 6 – Critérios de avaliação de Robustez Estrutural (Structural Robustness)
A47: Indicadores | B47: Inaceitável – 1 Ponto | C47: Fraco – 2 Pontos | D47: Aceitável – 3 Pontos | E47: Bom – 4 Pontos | F47: Excelente – 5 Pontos
A48: 6.1_protecao_ip_agua | B48: Infiltração de água (gotas). Falha crítica. | C48: Condensação interna excessiva (risco de curto). | D48: Condensação interna, com pouca água líquida (risco de curto). | E48: Leve condensação, sem água líquida (limitação). | F48: 100% seco (sem condensação).
A49: 6.2_resistencia_termica | B49: Infiltração de água de chuva. Falha crítica. | C49: Infiltração de poeira e insetos (risco inadequado). | D49: Presença de poeira, sem umidade (limitação). | E49: 100% seco, mas com poeira/insetos. | F49: 100% seco e limpo (sem poeira/insetos).
A50: 6.3_integridade_mecanica | B50: Falha estrutural (tombou, virou, quebrou). | C50: Instável (danificado limitando a estabilidade) | D50: Estável, mas com limitações | E50: Robusto, sem inclinação. | F50: Excelente estabilidade em vento/ondas.
...

Sheet Consulta
B3: Avaliação 1 | C3: Nota | D3: Pontuação
B4: Critétio 1 | C4: 2 | D4: {=_xlfn.IFS(C4=1,Dados!B5,C4=2,Dados!C5,C4=3,Dados!D5,C4=4,Dados!E5,C4=5,Dados!F5)} -> Erro entre 10-20%. | F4: Avaliação 1 | G4: =AVERAGE(C4:C9) -> 3.6
B5: Critétio 2 | C5: 4 | D5: {=_xlfn.IFS(C5=1,Dados!B6,C5=2,Dados!C6,C5=3,Dados!D6,C5=4,Dados!E6,C5=5,Dados!F6)} -> Erro < 10%. Funcionamento robusto. | F5: Avaliação 2 | G5: =AVERAGE(C13:C18) -> 3
B6: Critétio 3 | C6: 2 | D6: {=_xlfn.IFS(C6=1,Dados!B7,C6=2,Dados!C7,C6=3,Dados!D7,C6=4,Dados!E7,C6=5,Dados!F7)} -> Deriva > 15%. Dados das últimas semanas inutilizáveis, requer revisão de projeto. | F6: Avaliação 3 | G6: =AVERAGE(C22:C26) -> 3.4
B7: Critétio 4 | C7: 5 | D7: {=_xlfn.IFS(C7=1,Dados!B8,C7=2,Dados!C8,C7=3,Dados!D8,C7=4,Dados!E8,C7=5,Dados!F8)} -> < 30 s. | F7: Avaliação 4 | G7: =AVERAGE(C29:C32) -> 3.75
B8: Critétio 5 | C8: 5 | D8: {=_xlfn.IFS(C8=1,Dados!B9,C8=2,Dados!C9,C8=3,Dados!D9,C8=4,Dados!E9,C8=5,Dados!F9)} -> 1 | F8: Avaliação 5 | G8: =AVERAGE(C36:C39) -> 1.5
F9: Avaliação 6 | G9: =AVERAGE(C43:C47) -> 4.8
F10: Avaliação 7 | G10: =AVERAGE(C50:C54) -> 4.2
B11: Coluna1 | C11: Coluna2 | D11: Coluna3 | F11: Avaliação 8 | G11: =AVERAGE(C57:C61) -> 3.4
B12: Avaliação 2 | D12: Pontuação
B13: Critétio 1 | C13: 4 | D13: {=_xlfn.IFS(C13=1,Dados!B14,C13=2,Dados!C14,C13=3,Dados!D14,C13=4,Dados!E14,C13=5,Dados!F14)} -> Custo baixo, desempenho bom (robusto).
B14: Critétio 2 | C14: 5 | D14: {=_xlfn.IFS(C14=1,Dados!B15,C14=2,Dados!C15,C14=3,Dados!D15,C14=4,Dados!E15,C14=5,Dados!F15)} -> Custo < 10% do MVP/ano.
B15: Critétio 3 | C15: 3 | D15: {=_xlfn.IFS(C15=1,Dados!B16,C15=2,Dados!C16,C15=3,Dados!D16,C15=4,Dados!E16,C15=5,Dados!F16)} -> Média de 1-2 horas/unidade (limitação de tempo).
B16: Critétio 4 | C16: 1 | D16: {=_xlfn.IFS(C16=1,Dados!B17,C16=2,Dados!C17,C16=3,Dados!D17,C16=4,Dados!E17,C16=5,Dados!F17)} -> Processo artesanal, inviável de replicar.
B17: Critétio 5 | C17: 2 | D17: {=_xlfn.IFS(C17=1,Dados!B18,C17=2,Dados!C18,C17=3,Dados!D18,C17=4,Dados!E18,C17=5,Dados!F18)} -> TCO 10-20% abaixo. Diferencial inadequado.
B20: Coluna1 | C20: Coluna2 | D20: Coluna3
B21: Avaliação 3 | D21: Pontuação
B22: Critétio 1 | C22: 1 | D22: {=_xlfn.IFS(C22=1,Dados!B23,C22=2,Dados!C23,C22=3,Dados!D23,C22=4,Dados!E23,C22=5,Dados!F23)} -> Erro > 20%
B23: Critétio 2 | C23: 1 | D23: {=_xlfn.IFS(C23=1,Dados!B24,C23=2,Dados!C24,C23=3,Dados!D24,C23=4,Dados!E24,C23=5,Dados!F24)} -> Perda severa (> 25%), invalidou os dados.
B24: Critétio 3 | C24: 5 | D24: {=_xlfn.IFS(C24=1,Dados!B25,C24=2,Dados!C25,C24=3,Dados!D25,C24=4,Dados!E25,C24=5,Dados!F25)} -> 0 resets (100% estável).
B25: Critétio 4 | C25: 5 | D25: {=_xlfn.IFS(C25=1,Dados!B26,C25=2,Dados!C26,C25=3,Dados!D26,C25=4,Dados!E26,C25=5,Dados!F26)} -> Recuperação rápida (< 1 min).
B26: Critétio 5 | C26: 5 | D26: {=_xlfn.IFS(C26=1,Dados!B27,C26=2,Dados!C27,C26=3,Dados!D27,C26=4,Dados!E27,C26=5,Dados!F27)} -> Variabilidade < 2% (excelente).
B28: Avaliação 4 | C28: Coluna1 | D28: Pontuação
B29: Critétio 1 | C29: 4 | D29: {=_xlfn.IFS(C29=1,Dados!B32,C29=2,Dados!C32,C29=3,Dados!D32,C29=4,Dados!E32,C29=5,Dados!F32)} -> 30-60 min/unidade; 1 pessoa.
B30: Critétio 2 | C30: 4 | D30: {=_xlfn.IFS(C30=1,Dados!B33,C30=2,Dados!C33,C30=3,Dados!D33,C30=4,Dados!E33,C30=5,Dados!F33)} -> Rápido (via app), < 5 min.
B31: Critétio 3 | C31: 5 | D31: {=_xlfn.IFS(C31=1,Dados!B34,C31=2,Dados!C34,C31=3,Dados!D34,C31=4,Dados!E34,C31=5,Dados!F34)} -> Usuário encontra < 30 segundos (prático).
B32: Critétio 4 | C32: 2 | D32: {=_xlfn.IFS(C32=1,Dados!B35,C32=2,Dados!C35,C32=3,Dados!D35,C32=4,Dados!E35,C32=5,Dados!F35)} -> "Verde" com falha
B33: Critétio 5 | C33: 2 | D33: {=_xlfn.IFS(C33=1,Dados!B36,C33=2,Dados!C36,C33=3,Dados!D36,C33=4,Dados!E36,C33=5,Dados!F36)} -> 0
B35: Avaliação 5 | C35: Coluna1 | D35: Pontuação
B36: Critétio 1 | C36: 1 | D36: {=_xlfn.IFS(C36=1,Dados!B40,C36=2,Dados!C40,C36=3,Dados!D40,C36=4,Dados!E40,C36=5,Dados!F40)} -> Uma ou mais réplicas (n=5) desligaram por falta de energia.
B37: Critétio 2 | C37: 1 | D37: {=_xlfn.IFS(C37=1,Dados!B41,C37=2,Dados!C41,C37=3,Dados!D41,C37=4,Dados!E41,C37=5,Dados!F41)} -> Requer > 1 dia de sol para recarga.
B38: Critétio 3 | C38: 1 | D38: {=_xlfn.IFS(C38=1,Dados!B42,C38=2,Dados!C42,C38=3,Dados!D42,C38=4,Dados!E42,C38=5,Dados!F42)} -> Alto consumo (bateria > 5 dias).
B39: Critétio 4 | C39: 3 | D39: {=_xlfn.IFS(C39=1,Dados!B43,C39=2,Dados!C43,C39=3,Dados!D43,C39=4,Dados!E43,C39=5,Dados!F43)} -> Aceitável, mas sem margem de segurança.
B40: Critétio 5 | D40: {=_xlfn.IFS(C40=1,Dados!B44,C40=2,Dados!C44,C40=3,Dados!D44,C40=4,Dados!E44,C40=5,Dados!F44)} -> #N/A
B42: Avaliação 6 | C42: Coluna1 | D42: Pontuação
B43: Critétio 1 | C43: 5 | D43: {=_xlfn.IFS(C43=1,Dados!B48,C43=2,Dados!C48,C43=3,Dados!D48,C43=4,Dados!E48,C43=5,Dados!F48)} -> 100% seco (sem condensação).
B44: Critétio 2 | C44: 5 | D44: {=_xlfn.IFS(C44=1,Dados!B49,C44=2,Dados!C49,C44=3,Dados!D49,C44=4,Dados!E49,C44=5,Dados!F49)} -> 100% seco e limpo (sem poeira/insetos).
B45: Critétio 3 | C45: 5 | D45: {=_xlfn.IFS(C45=1,Dados!B50,C45=2,Dados!C50,C45=3,Dados!D50,C45=4,Dados!E50,C45=5,Dados!F50)} -> Excelente estabilidade em vento/ondas.
B46: Critétio 4 | C46: 5 | D46: {=_xlfn.IFS(C46=1,Dados!B51,C46=2,Dados!C51,C46=3,Dados!D51,C46=4,Dados!E51,C46=5,Dados!F51)} -> Excelente estabilidade.
B47: Critétio 5 | C47: 4 | D47: {=_xlfn.IFS(C47=1,Dados!B52,C47=2,Dados!C52,C47=3,Dados!D52,C47=4,Dados!E52,C47=5,Dados!F52)} -> Componentes com pouca danificação.
...
